import pytest
from unittest.mock import patch, MagicMock
import sys
from main import main


def test_main_success():
    """Test main function successful execution."""
    with patch('main.mcp') as mock_mcp:
        mock_mcp.run.return_value = None
        
        main()
        
        mock_mcp.run.assert_called_once()


def test_main_unicode_decode_error():
    """Test main function with UnicodeDecodeError."""
    with patch('main.mcp') as mock_mcp, \
         patch('sys.exit') as mock_exit:
        
        mock_mcp.run.side_effect = Exception("UnicodeDecodeError occurred")
        
        main()
        
        mock_exit.assert_called_once_with(0)


def test_main_exception_group():
    """Test main function with ExceptionGroup."""
    with patch('main.mcp') as mock_mcp, \
         patch('sys.exit') as mock_exit:
        
        # Create a mock exception with ExceptionGroup in type name
        mock_exception = Exception("Test error")
        mock_exception.__class__.__name__ = "ExceptionGroup"
        mock_mcp.run.side_effect = mock_exception
        
        main()
        
        mock_exit.assert_called_once_with(0)


def test_main_other_exception():
    """Test main function with other exceptions."""
    with patch('main.mcp') as mock_mcp:
        mock_mcp.run.side_effect = ValueError("Other error")
        
        with pytest.raises(ValueError, match="Other error"):
            main()


def test_main_entry_point():
    """Test main entry point execution."""
    with patch('main.main') as mock_main_func, \
         patch('__main__.__name__', '__main__'):
        
        # This would normally execute main() when run as script
        # We just test the function exists and can be called
        mock_main_func()
        mock_main_func.assert_called_once()